Performing system checks...

System check identified no issues (0 silenced).
March 31, 2019 - 22:32:39
Django version 2.1.7, using settings 'MedusaII.settings'
Starting development server at http://0.0.0.0:8000/
Quit the server with CTRL-BREAK.
2019-03-31 22:34:43,324 escola.views 20644 INFO     views:index; user_id: 1
2019-03-31 22:34:43,329 escola.views 20644 INFO     views:index; user_id: 1 é aluno.
2019-03-31 22:34:43,329 escola.views 20644 INFO     Lembre-se de retirar as tarefas daqui e generalizar;
2019-03-31 22:34:43,332 escola.views 20644 DEBUG    Encontrei 1 tarefas.
2019-03-31 22:34:43,333 escola.views 20644 INFO     Antes de renderizar a view index, user: 1
2019-03-31 22:34:43,495 escola.models 20644 DEBUG    horario:get_horario()
2019-03-31 22:34:43,497 escola.models 20644 INFO     Puxou 3 turno(s) do banco de dados.
2019-03-31 22:34:43,498 escola.models 20644 INFO     Preparando para entrar no loop de turnos...
2019-03-31 22:34:43,498 escola.models 20644 DEBUG    Turno id:1
2019-03-31 22:34:43,509 escola.models 20644 DEBUG    Turno id:3
2019-03-31 22:34:43,521 escola.models 20644 DEBUG    Turno id:2
Performing system checks...

System check identified no issues (0 silenced).
March 31, 2019 - 22:35:35
Django version 2.1.7, using settings 'MedusaII.settings'
Starting development server at http://0.0.0.0:8000/
Quit the server with CTRL-BREAK.
2019-03-31 22:46:42,996 django.request 17996 WARNING  Not Found: /HNAP1/
2019-03-31 22:46:45,106 django.server 17996 WARNING  "GET /HNAP1/ HTTP/1.1" 404 9952
Traceback (most recent call last):
  File "c:\users\wwwvi\appdata\local\programs\python\python37-32\Lib\wsgiref\handlers.py", line 138, in run
    self.finish_response()
  File "c:\users\wwwvi\appdata\local\programs\python\python37-32\Lib\wsgiref\handlers.py", line 180, in finish_response
    self.write(data)
  File "c:\users\wwwvi\appdata\local\programs\python\python37-32\Lib\wsgiref\handlers.py", line 274, in write
    self.send_headers()
  File "c:\users\wwwvi\appdata\local\programs\python\python37-32\Lib\wsgiref\handlers.py", line 332, in send_headers
    self.send_preamble()
  File "c:\users\wwwvi\appdata\local\programs\python\python37-32\Lib\wsgiref\handlers.py", line 255, in send_preamble
    ('Date: %s\r\n' % format_date_time(time.time())).encode('iso-8859-1')
  File "c:\users\wwwvi\appdata\local\programs\python\python37-32\Lib\wsgiref\handlers.py", line 453, in _write
    result = self.stdout.write(data)
  File "c:\users\wwwvi\appdata\local\programs\python\python37-32\Lib\socketserver.py", line 796, in write
    self._sock.sendall(b)
ConnectionAbortedError: [WinError 10053] Uma conexão estabelecida foi anulada pelo software no computador host
2019-03-31 22:46:45,133 django.server 17996 ERROR    "GET /HNAP1/ HTTP/1.1" 500 59
----------------------------------------
Exception happened during processing of request from ('10.0.0.102', 53691)
Traceback (most recent call last):
  File "c:\users\wwwvi\appdata\local\programs\python\python37-32\Lib\wsgiref\handlers.py", line 138, in run
    self.finish_response()
  File "c:\users\wwwvi\appdata\local\programs\python\python37-32\Lib\wsgiref\handlers.py", line 180, in finish_response
    self.write(data)
  File "c:\users\wwwvi\appdata\local\programs\python\python37-32\Lib\wsgiref\handlers.py", line 274, in write
    self.send_headers()
  File "c:\users\wwwvi\appdata\local\programs\python\python37-32\Lib\wsgiref\handlers.py", line 332, in send_headers
    self.send_preamble()
  File "c:\users\wwwvi\appdata\local\programs\python\python37-32\Lib\wsgiref\handlers.py", line 255, in send_preamble
    ('Date: %s\r\n' % format_date_time(time.time())).encode('iso-8859-1')
  File "c:\users\wwwvi\appdata\local\programs\python\python37-32\Lib\wsgiref\handlers.py", line 453, in _write
    result = self.stdout.write(data)
  File "c:\users\wwwvi\appdata\local\programs\python\python37-32\Lib\socketserver.py", line 796, in write
    self._sock.sendall(b)
ConnectionAbortedError: [WinError 10053] Uma conexão estabelecida foi anulada pelo software no computador host

During handling of the above exception, another exception occurred:

Traceback (most recent call last):
  File "c:\users\wwwvi\appdata\local\programs\python\python37-32\Lib\wsgiref\handlers.py", line 141, in run
    self.handle_error()
  File "C:\Programação\Medusa II\.vEnv\lib\site-packages\django\core\servers\basehttp.py", line 116, in handle_error
    super().handle_error()
  File "c:\users\wwwvi\appdata\local\programs\python\python37-32\Lib\wsgiref\handlers.py", line 368, in handle_error
    self.finish_response()
  File "c:\users\wwwvi\appdata\local\programs\python\python37-32\Lib\wsgiref\handlers.py", line 180, in finish_response
    self.write(data)
  File "c:\users\wwwvi\appdata\local\programs\python\python37-32\Lib\wsgiref\handlers.py", line 274, in write
    self.send_headers()
  File "c:\users\wwwvi\appdata\local\programs\python\python37-32\Lib\wsgiref\handlers.py", line 331, in send_headers
    if not self.origin_server or self.client_is_modern():
  File "c:\users\wwwvi\appdata\local\programs\python\python37-32\Lib\wsgiref\handlers.py", line 344, in client_is_modern
    return self.environ['SERVER_PROTOCOL'].upper() != 'HTTP/0.9'
TypeError: 'NoneType' object is not subscriptable

During handling of the above exception, another exception occurred:

Traceback (most recent call last):
  File "c:\users\wwwvi\appdata\local\programs\python\python37-32\Lib\socketserver.py", line 647, in process_request_thread
    self.finish_request(request, client_address)
  File "c:\users\wwwvi\appdata\local\programs\python\python37-32\Lib\socketserver.py", line 357, in finish_request
    self.RequestHandlerClass(request, client_address, self)
  File "c:\users\wwwvi\appdata\local\programs\python\python37-32\Lib\socketserver.py", line 717, in __init__
    self.handle()
  File "C:\Programação\Medusa II\.vEnv\lib\site-packages\django\core\servers\basehttp.py", line 169, in handle
    self.handle_one_request()
  File "C:\Programação\Medusa II\.vEnv\lib\site-packages\django\core\servers\basehttp.py", line 194, in handle_one_request
    handler.run(self.server.get_app())
  File "c:\users\wwwvi\appdata\local\programs\python\python37-32\Lib\wsgiref\handlers.py", line 144, in run
    self.close()
  File "C:\Programação\Medusa II\.vEnv\lib\site-packages\django\core\servers\basehttp.py", line 111, in close
    super().close()
  File "c:\users\wwwvi\appdata\local\programs\python\python37-32\Lib\wsgiref\simple_server.py", line 35, in close
    self.status.split(' ',1)[0], self.bytes_sent
AttributeError: 'NoneType' object has no attribute 'split'
----------------------------------------
2019-04-01 20:43:13,906 escola.views 2196 INFO     views:index; user_id: 1
2019-04-01 20:43:14,058 escola.views 2196 INFO     views:index; user_id: 1 é aluno.
2019-04-01 20:43:14,058 escola.views 2196 INFO     Lembre-se de retirar as tarefas daqui e generalizar;
2019-04-01 20:43:14,260 escola.views 2196 DEBUG    Encontrei 1 tarefas.
2019-04-01 20:43:14,285 escola.views 2196 INFO     Antes de renderizar a view index, user: 1
2019-04-01 20:43:15,451 escola.models 2196 DEBUG    horario:get_horario()
2019-04-01 20:43:15,500 escola.models 2196 INFO     Puxou 3 turno(s) do banco de dados.
2019-04-01 20:43:15,500 escola.models 2196 INFO     Preparando para entrar no loop de turnos...
2019-04-01 20:43:15,500 escola.models 2196 DEBUG    Turno id:1
2019-04-01 20:43:15,614 escola.models 2196 DEBUG    Turno id:3
2019-04-01 20:43:15,623 escola.models 2196 DEBUG    Turno id:2
Performing system checks...

System check identified no issues (0 silenced).
April 01, 2019 - 21:23:08
Django version 2.1.7, using settings 'MedusaII.settings'
Starting development server at http://0.0.0.0:8000/
Quit the server with CTRL-BREAK.
2019-04-01 22:50:57,891 django.request 14536 WARNING  Not Found: /HNAP1/
2019-04-01 22:51:02,460 django.server 14536 WARNING  "GET /HNAP1/ HTTP/1.1" 404 9952
Traceback (most recent call last):
  File "c:\users\wwwvi\appdata\local\programs\python\python37-32\Lib\wsgiref\handlers.py", line 138, in run
    self.finish_response()
  File "c:\users\wwwvi\appdata\local\programs\python\python37-32\Lib\wsgiref\handlers.py", line 180, in finish_response
    self.write(data)
  File "c:\users\wwwvi\appdata\local\programs\python\python37-32\Lib\wsgiref\handlers.py", line 274, in write
    self.send_headers()
  File "c:\users\wwwvi\appdata\local\programs\python\python37-32\Lib\wsgiref\handlers.py", line 332, in send_headers
    self.send_preamble()
  File "c:\users\wwwvi\appdata\local\programs\python\python37-32\Lib\wsgiref\handlers.py", line 255, in send_preamble
    ('Date: %s\r\n' % format_date_time(time.time())).encode('iso-8859-1')
  File "c:\users\wwwvi\appdata\local\programs\python\python37-32\Lib\wsgiref\handlers.py", line 453, in _write
    result = self.stdout.write(data)
  File "c:\users\wwwvi\appdata\local\programs\python\python37-32\Lib\socketserver.py", line 796, in write
    self._sock.sendall(b)
ConnectionAbortedError: [WinError 10053] Uma conexão estabelecida foi anulada pelo software no computador host
2019-04-01 22:51:02,485 django.server 14536 ERROR    "GET /HNAP1/ HTTP/1.1" 500 59
----------------------------------------
Exception happened during processing of request from ('10.0.0.102', 50313)
Traceback (most recent call last):
  File "c:\users\wwwvi\appdata\local\programs\python\python37-32\Lib\wsgiref\handlers.py", line 138, in run
    self.finish_response()
  File "c:\users\wwwvi\appdata\local\programs\python\python37-32\Lib\wsgiref\handlers.py", line 180, in finish_response
    self.write(data)
  File "c:\users\wwwvi\appdata\local\programs\python\python37-32\Lib\wsgiref\handlers.py", line 274, in write
    self.send_headers()
  File "c:\users\wwwvi\appdata\local\programs\python\python37-32\Lib\wsgiref\handlers.py", line 332, in send_headers
    self.send_preamble()
  File "c:\users\wwwvi\appdata\local\programs\python\python37-32\Lib\wsgiref\handlers.py", line 255, in send_preamble
    ('Date: %s\r\n' % format_date_time(time.time())).encode('iso-8859-1')
  File "c:\users\wwwvi\appdata\local\programs\python\python37-32\Lib\wsgiref\handlers.py", line 453, in _write
    result = self.stdout.write(data)
  File "c:\users\wwwvi\appdata\local\programs\python\python37-32\Lib\socketserver.py", line 796, in write
    self._sock.sendall(b)
ConnectionAbortedError: [WinError 10053] Uma conexão estabelecida foi anulada pelo software no computador host

During handling of the above exception, another exception occurred:

Traceback (most recent call last):
  File "c:\users\wwwvi\appdata\local\programs\python\python37-32\Lib\wsgiref\handlers.py", line 141, in run
    self.handle_error()
  File "C:\Programação\Medusa II\.vEnv\lib\site-packages\django\core\servers\basehttp.py", line 116, in handle_error
    super().handle_error()
  File "c:\users\wwwvi\appdata\local\programs\python\python37-32\Lib\wsgiref\handlers.py", line 368, in handle_error
    self.finish_response()
  File "c:\users\wwwvi\appdata\local\programs\python\python37-32\Lib\wsgiref\handlers.py", line 180, in finish_response
    self.write(data)
  File "c:\users\wwwvi\appdata\local\programs\python\python37-32\Lib\wsgiref\handlers.py", line 274, in write
    self.send_headers()
  File "c:\users\wwwvi\appdata\local\programs\python\python37-32\Lib\wsgiref\handlers.py", line 331, in send_headers
    if not self.origin_server or self.client_is_modern():
  File "c:\users\wwwvi\appdata\local\programs\python\python37-32\Lib\wsgiref\handlers.py", line 344, in client_is_modern
    return self.environ['SERVER_PROTOCOL'].upper() != 'HTTP/0.9'
TypeError: 'NoneType' object is not subscriptable

During handling of the above exception, another exception occurred:

Traceback (most recent call last):
  File "c:\users\wwwvi\appdata\local\programs\python\python37-32\Lib\socketserver.py", line 647, in process_request_thread
    self.finish_request(request, client_address)
  File "c:\users\wwwvi\appdata\local\programs\python\python37-32\Lib\socketserver.py", line 357, in finish_request
    self.RequestHandlerClass(request, client_address, self)
  File "c:\users\wwwvi\appdata\local\programs\python\python37-32\Lib\socketserver.py", line 717, in __init__
    self.handle()
  File "C:\Programação\Medusa II\.vEnv\lib\site-packages\django\core\servers\basehttp.py", line 169, in handle
    self.handle_one_request()
  File "C:\Programação\Medusa II\.vEnv\lib\site-packages\django\core\servers\basehttp.py", line 194, in handle_one_request
    handler.run(self.server.get_app())
  File "c:\users\wwwvi\appdata\local\programs\python\python37-32\Lib\wsgiref\handlers.py", line 144, in run
    self.close()
  File "C:\Programação\Medusa II\.vEnv\lib\site-packages\django\core\servers\basehttp.py", line 111, in close
    super().close()
  File "c:\users\wwwvi\appdata\local\programs\python\python37-32\Lib\wsgiref\simple_server.py", line 35, in close
    self.status.split(' ',1)[0], self.bytes_sent
AttributeError: 'NoneType' object has no attribute 'split'
----------------------------------------
