Performing system checks...

System check identified no issues (0 silenced).
April 03, 2019 - 21:04:31
Django version 2.1.7, using settings 'MedusaII.settings'
Starting development server at http://0.0.0.0:8000/
Quit the server with CTRL-BREAK.
2019-04-03 21:05:05,709 escola.views 18912 INFO     views:index; user_id: 1
2019-04-03 21:05:05,818 escola.views 18912 INFO     views:index; user_id: 1 é aluno.
2019-04-03 21:05:05,818 escola.views 18912 INFO     Lembre-se de retirar as tarefas daqui e generalizar;
2019-04-03 21:05:05,898 escola.views 18912 DEBUG    Encontrei 1 tarefas.
2019-04-03 21:05:05,899 escola.views 18912 INFO     Antes de renderizar a view index, user: 1
2019-04-03 21:05:06,336 escola.models 18912 DEBUG    horario:get_horario()
2019-04-03 21:05:06,352 escola.models 18912 INFO     Puxou 3 turno(s) do banco de dados.
2019-04-03 21:05:06,352 escola.models 18912 INFO     Preparando para entrar no loop de turnos...
2019-04-03 21:05:06,352 escola.models 18912 DEBUG    Turno id:1
2019-04-03 21:05:06,367 escola.models 18912 DEBUG    Turno id:3
2019-04-03 21:05:06,376 escola.models 18912 DEBUG    Turno id:2
Traceback (most recent call last):
  File "c:\users\wwwvi\appdata\local\programs\python\python37-32\Lib\wsgiref\handlers.py", line 138, in run
    self.finish_response()
  File "c:\users\wwwvi\appdata\local\programs\python\python37-32\Lib\wsgiref\handlers.py", line 180, in finish_response
    self.write(data)
  File "c:\users\wwwvi\appdata\local\programs\python\python37-32\Lib\wsgiref\handlers.py", line 274, in write
    self.send_headers()
  File "c:\users\wwwvi\appdata\local\programs\python\python37-32\Lib\wsgiref\handlers.py", line 332, in send_headers
    self.send_preamble()
  File "c:\users\wwwvi\appdata\local\programs\python\python37-32\Lib\wsgiref\handlers.py", line 255, in send_preamble
    ('Date: %s\r\n' % format_date_time(time.time())).encode('iso-8859-1')
  File "c:\users\wwwvi\appdata\local\programs\python\python37-32\Lib\wsgiref\handlers.py", line 453, in _write
    result = self.stdout.write(data)
  File "c:\users\wwwvi\appdata\local\programs\python\python37-32\Lib\socketserver.py", line 796, in write
    self._sock.sendall(b)
ConnectionAbortedError: [WinError 10053] Uma conexão estabelecida foi anulada pelo software no computador host
2019-04-04 12:38:38,992 django.server 10336 ERROR    "GET / HTTP/1.1" 500 59
----------------------------------------
Exception happened during processing of request from ('10.0.0.102', 59567)
Traceback (most recent call last):
  File "c:\users\wwwvi\appdata\local\programs\python\python37-32\Lib\wsgiref\handlers.py", line 138, in run
    self.finish_response()
  File "c:\users\wwwvi\appdata\local\programs\python\python37-32\Lib\wsgiref\handlers.py", line 180, in finish_response
    self.write(data)
  File "c:\users\wwwvi\appdata\local\programs\python\python37-32\Lib\wsgiref\handlers.py", line 274, in write
    self.send_headers()
  File "c:\users\wwwvi\appdata\local\programs\python\python37-32\Lib\wsgiref\handlers.py", line 332, in send_headers
    self.send_preamble()
  File "c:\users\wwwvi\appdata\local\programs\python\python37-32\Lib\wsgiref\handlers.py", line 255, in send_preamble
    ('Date: %s\r\n' % format_date_time(time.time())).encode('iso-8859-1')
  File "c:\users\wwwvi\appdata\local\programs\python\python37-32\Lib\wsgiref\handlers.py", line 453, in _write
    result = self.stdout.write(data)
  File "c:\users\wwwvi\appdata\local\programs\python\python37-32\Lib\socketserver.py", line 796, in write
    self._sock.sendall(b)
ConnectionAbortedError: [WinError 10053] Uma conexão estabelecida foi anulada pelo software no computador host

During handling of the above exception, another exception occurred:

Traceback (most recent call last):
  File "c:\users\wwwvi\appdata\local\programs\python\python37-32\Lib\wsgiref\handlers.py", line 141, in run
    self.handle_error()
  File "C:\Programação\Medusa II\.vEnv\lib\site-packages\django\core\servers\basehttp.py", line 116, in handle_error
    super().handle_error()
  File "c:\users\wwwvi\appdata\local\programs\python\python37-32\Lib\wsgiref\handlers.py", line 368, in handle_error
    self.finish_response()
  File "c:\users\wwwvi\appdata\local\programs\python\python37-32\Lib\wsgiref\handlers.py", line 180, in finish_response
    self.write(data)
  File "c:\users\wwwvi\appdata\local\programs\python\python37-32\Lib\wsgiref\handlers.py", line 274, in write
    self.send_headers()
  File "c:\users\wwwvi\appdata\local\programs\python\python37-32\Lib\wsgiref\handlers.py", line 331, in send_headers
    if not self.origin_server or self.client_is_modern():
  File "c:\users\wwwvi\appdata\local\programs\python\python37-32\Lib\wsgiref\handlers.py", line 344, in client_is_modern
    return self.environ['SERVER_PROTOCOL'].upper() != 'HTTP/0.9'
TypeError: 'NoneType' object is not subscriptable

During handling of the above exception, another exception occurred:

Traceback (most recent call last):
  File "c:\users\wwwvi\appdata\local\programs\python\python37-32\Lib\socketserver.py", line 647, in process_request_thread
    self.finish_request(request, client_address)
  File "c:\users\wwwvi\appdata\local\programs\python\python37-32\Lib\socketserver.py", line 357, in finish_request
    self.RequestHandlerClass(request, client_address, self)
  File "c:\users\wwwvi\appdata\local\programs\python\python37-32\Lib\socketserver.py", line 717, in __init__
    self.handle()
  File "C:\Programação\Medusa II\.vEnv\lib\site-packages\django\core\servers\basehttp.py", line 169, in handle
    self.handle_one_request()
  File "C:\Programação\Medusa II\.vEnv\lib\site-packages\django\core\servers\basehttp.py", line 194, in handle_one_request
    handler.run(self.server.get_app())
  File "c:\users\wwwvi\appdata\local\programs\python\python37-32\Lib\wsgiref\handlers.py", line 144, in run
    self.close()
  File "C:\Programação\Medusa II\.vEnv\lib\site-packages\django\core\servers\basehttp.py", line 111, in close
    super().close()
  File "c:\users\wwwvi\appdata\local\programs\python\python37-32\Lib\wsgiref\simple_server.py", line 35, in close
    self.status.split(' ',1)[0], self.bytes_sent
AttributeError: 'NoneType' object has no attribute 'split'
----------------------------------------
